INFO:tg bot:Income bot start
INFO:requests.packages.urllib3.connectionpool:Starting new HTTPS connection (1): api.telegram.org
ERROR:TeleBot:ConnectTimeout occurred, args=(MaxRetryError("HTTPSConnectionPool(host='api.telegram.org', port=443): Max retries exceeded with url: /bot815328183:AAEzdOs3Bir1terISfyN2EtVbrzqZ6Aa6Tw/getUpdates?offset=1&timeout=20 (Caused by ConnectTimeoutError(<requests.packages.urllib3.connection.VerifiedHTTPSConnection object at 0x00000151A5CD8CC0>, 'Connection to api.telegram.org timed out. (connect timeout=3.5)'))"),)
Traceback (most recent call last):
  File "E:\programers_files\Projects\IncomeBot\venv\lib\site-packages\requests\packages\urllib3\connection.py", line 134, in _new_conn
    (self.host, self.port), self.timeout, **extra_kw)
  File "E:\programers_files\Projects\IncomeBot\venv\lib\site-packages\requests\packages\urllib3\util\connection.py", line 88, in create_connection
    raise err
  File "E:\programers_files\Projects\IncomeBot\venv\lib\site-packages\requests\packages\urllib3\util\connection.py", line 78, in create_connection
    sock.connect(sa)
socket.timeout: timed out

During handling of the above exception, another exception occurred:

Traceback (most recent call last):
  File "E:\programers_files\Projects\IncomeBot\venv\lib\site-packages\requests\packages\urllib3\connectionpool.py", line 544, in urlopen
    body=body, headers=headers)
  File "E:\programers_files\Projects\IncomeBot\venv\lib\site-packages\requests\packages\urllib3\connectionpool.py", line 341, in _make_request
    self._validate_conn(conn)
  File "E:\programers_files\Projects\IncomeBot\venv\lib\site-packages\requests\packages\urllib3\connectionpool.py", line 761, in _validate_conn
    conn.connect()
  File "E:\programers_files\Projects\IncomeBot\venv\lib\site-packages\requests\packages\urllib3\connection.py", line 204, in connect
    conn = self._new_conn()
  File "E:\programers_files\Projects\IncomeBot\venv\lib\site-packages\requests\packages\urllib3\connection.py", line 139, in _new_conn
    (self.host, self.timeout))
requests.packages.urllib3.exceptions.ConnectTimeoutError: (<requests.packages.urllib3.connection.VerifiedHTTPSConnection object at 0x00000151A5CD8CC0>, 'Connection to api.telegram.org timed out. (connect timeout=3.5)')

During handling of the above exception, another exception occurred:

Traceback (most recent call last):
  File "E:\programers_files\Projects\IncomeBot\venv\lib\site-packages\requests\adapters.py", line 370, in send
    timeout=timeout
  File "E:\programers_files\Projects\IncomeBot\venv\lib\site-packages\requests\packages\urllib3\connectionpool.py", line 597, in urlopen
    _stacktrace=sys.exc_info()[2])
  File "E:\programers_files\Projects\IncomeBot\venv\lib\site-packages\requests\packages\urllib3\util\retry.py", line 271, in increment
    raise MaxRetryError(_pool, url, error or ResponseError(cause))
requests.packages.urllib3.exceptions.MaxRetryError: HTTPSConnectionPool(host='api.telegram.org', port=443): Max retries exceeded with url: /bot815328183:AAEzdOs3Bir1terISfyN2EtVbrzqZ6Aa6Tw/getUpdates?offset=1&timeout=20 (Caused by ConnectTimeoutError(<requests.packages.urllib3.connection.VerifiedHTTPSConnection object at 0x00000151A5CD8CC0>, 'Connection to api.telegram.org timed out. (connect timeout=3.5)'))

During handling of the above exception, another exception occurred:

Traceback (most recent call last):
  File "E:\programers_files\Projects\IncomeBot\venv\lib\site-packages\telebot\util.py", line 59, in run
    task(*args, **kwargs)
  File "E:\programers_files\Projects\IncomeBot\venv\lib\site-packages\telebot\__init__.py", line 276, in __retrieve_updates
    updates = self.get_updates(offset=(self.last_update_id + 1), timeout=timeout)
  File "E:\programers_files\Projects\IncomeBot\venv\lib\site-packages\telebot\__init__.py", line 246, in get_updates
    json_updates = apihelper.get_updates(self.token, offset, limit, timeout, allowed_updates)
  File "E:\programers_files\Projects\IncomeBot\venv\lib\site-packages\telebot\apihelper.py", line 180, in get_updates
    return _make_request(token, method_url, params=payload)
  File "E:\programers_files\Projects\IncomeBot\venv\lib\site-packages\telebot\apihelper.py", line 54, in _make_request
    timeout=(connect_timeout, read_timeout), proxies=proxy)
  File "E:\programers_files\Projects\IncomeBot\venv\lib\site-packages\requests\sessions.py", line 465, in request
    resp = self.send(prep, **send_kwargs)
  File "E:\programers_files\Projects\IncomeBot\venv\lib\site-packages\requests\sessions.py", line 573, in send
    r = adapter.send(request, **kwargs)
  File "E:\programers_files\Projects\IncomeBot\venv\lib\site-packages\requests\adapters.py", line 419, in send
    raise ConnectTimeout(e, request=request)
requests.exceptions.ConnectTimeout: HTTPSConnectionPool(host='api.telegram.org', port=443): Max retries exceeded with url: /bot815328183:AAEzdOs3Bir1terISfyN2EtVbrzqZ6Aa6Tw/getUpdates?offset=1&timeout=20 (Caused by ConnectTimeoutError(<requests.packages.urllib3.connection.VerifiedHTTPSConnection object at 0x00000151A5CD8CC0>, 'Connection to api.telegram.org timed out. (connect timeout=3.5)'))

INFO:tg bot:Error
INFO:tg bot:Income bot start
INFO:requests.packages.urllib3.connectionpool:Starting new HTTPS connection (1): api.telegram.org
INFO:tg bot:Income bot start
INFO:requests.packages.urllib3.connectionpool:Starting new HTTPS connection (1): api.telegram.org
INFO:tg bot:Income bot start
INFO:requests.packages.urllib3.connectionpool:Starting new HTTPS connection (1): api.telegram.org
INFO:requests.packages.urllib3.connectionpool:Starting new HTTPS connection (1): api.telegram.org
ERROR:TeleBot:TypeError occurred, args=("'Logger' object is not callable",)
Traceback (most recent call last):
  File "E:\programers_files\Projects\IncomeBot\venv\lib\site-packages\telebot\util.py", line 59, in run
    task(*args, **kwargs)
  File "E:/programers_files/Projects/IncomeBot/Bot/telsent.py", line 385, in repeat_all_messages
    log(str(message.from_user.last_name) + ' : ' + message.text)
TypeError: 'Logger' object is not callable

INFO:tg bot:Error
INFO:tg bot:Income bot start
INFO:requests.packages.urllib3.connectionpool:Starting new HTTPS connection (1): api.telegram.org
INFO:requests.packages.urllib3.connectionpool:Starting new HTTPS connection (1): api.telegram.org
INFO:requests.packages.urllib3.connectionpool:Starting new HTTPS connection (1): api.telegram.org
ERROR:TeleBot:ApiException occurred, args=('A request to the Telegram API was unsuccessful. The server returned HTTP 409 Conflict. Response body:\n[b\'{"ok":false,"error_code":409,"description":"Conflict: terminated by other getUpdates request; make sure that only one bot instance is running"}\']',)
Traceback (most recent call last):
  File "E:\programers_files\Projects\IncomeBot\venv\lib\site-packages\telebot\util.py", line 59, in run
    task(*args, **kwargs)
  File "E:\programers_files\Projects\IncomeBot\venv\lib\site-packages\telebot\__init__.py", line 276, in __retrieve_updates
    updates = self.get_updates(offset=(self.last_update_id + 1), timeout=timeout)
  File "E:\programers_files\Projects\IncomeBot\venv\lib\site-packages\telebot\__init__.py", line 246, in get_updates
    json_updates = apihelper.get_updates(self.token, offset, limit, timeout, allowed_updates)
  File "E:\programers_files\Projects\IncomeBot\venv\lib\site-packages\telebot\apihelper.py", line 180, in get_updates
    return _make_request(token, method_url, params=payload)
  File "E:\programers_files\Projects\IncomeBot\venv\lib\site-packages\telebot\apihelper.py", line 56, in _make_request
    return _check_result(method_name, result)['result']
  File "E:\programers_files\Projects\IncomeBot\venv\lib\site-packages\telebot\apihelper.py", line 75, in _check_result
    raise ApiException(msg, method_name, result)
telebot.apihelper.ApiException: A request to the Telegram API was unsuccessful. The server returned HTTP 409 Conflict. Response body:
[b'{"ok":false,"error_code":409,"description":"Conflict: terminated by other getUpdates request; make sure that only one bot instance is running"}']

ERROR:TeleBot:A request to the Telegram API was unsuccessful. The server returned HTTP 409 Conflict. Response body:
[b'{"ok":false,"error_code":409,"description":"Conflict: terminated by other getUpdates request; make sure that only one bot instance is running"}']
